mplus_output/uni-27-SHARE_W4.out
Mplus VERSION 8.1 (Mac)
MUTHEN & MUTHEN
05/27/2020  10:28 PM

INPUT INSTRUCTIONS

  DATA:
  FILE = "uni-27-SHARE_W4.dat";

  VARIABLE:
  NAMES = mplusid UDAT UDAY UMON UYER UIWR UDWR UANI URE3 URE4 URE6 USUB;
   MISSING=.;
   CATEGORICAL ARE all; idvariable = mplusid;
  ANALYSIS:
  estimator = wlsmv; coverage=0;
  MODEL:
  g by UDAT * ;
   g by UDAY * ;
   g by UMON * ;
   g by UYER * ;
   g by UIWR * ;
   g by UDWR * ;
   g by USUB * ;
   g by URE3 * ;
   g by URE6 * ;
   g by UANI * ;
   g by URE4 * ;
   g @ 1;

  OUTPUT:
  standardized; svalues;



*** WARNING
  Data set contains cases with missing on all variables.
  These cases were not included in the analysis.
  Number of cases with missing on all variables:  1134
   1 WARNING(S) FOUND IN THE INPUT INSTRUCTIONS




SUMMARY OF ANALYSIS

Number of groups                                                 1
Number of observations                                       57068

Number of dependent variables                                   11
Number of independent variables                                  0
Number of continuous latent variables                            1

Observed dependent variables

  Binary and ordered categorical (ordinal)
   UDAT        UDAY        UMON        UYER        UIWR        UDWR
   UANI        URE3        URE4        URE6        USUB

Continuous latent variables
   G

Variables with special functions

  ID variable           MPLUSID

Estimator                                                    WLSMV
Maximum number of iterations                                  1000
Convergence criterion                                    0.500D-04
Maximum number of steepest descent iterations                   20
Maximum number of iterations for H1                           2000
Convergence criterion for H1                             0.100D-03
Parameterization                                             DELTA
Link                                                        PROBIT

Input data file(s)
  uni-27-SHARE_W4.dat

Input data format  FREE


SUMMARY OF DATA

     Number of missing data patterns            97


COVARIANCE COVERAGE OF DATA

Minimum covariance coverage value   0.000


     PROPORTION OF DATA PRESENT


           Covariance Coverage
              UDAT          UDAY          UMON          UYER          UIWR
              ________      ________      ________      ________      ________
 UDAT           0.640
 UDAY           0.640         0.641
 UMON           0.640         0.641         0.641
 UYER           0.640         0.641         0.641         0.641
 UIWR           0.633         0.634         0.634         0.634         0.992
 UDWR           0.633         0.634         0.634         0.634         0.991
 UANI           0.632         0.633         0.633         0.633         0.984
 URE3           0.540         0.541         0.541         0.541         0.539
 URE4           0.434         0.434         0.434         0.434         0.432
 URE6           0.284         0.284         0.284         0.284         0.283
 USUB           0.612         0.612         0.612         0.612         0.950


           Covariance Coverage
              UDWR          UANI          URE3          URE4          URE6
              ________      ________      ________      ________      ________
 UDWR           0.992
 UANI           0.985         0.987
 URE3           0.539         0.539         0.541
 URE4           0.432         0.432         0.434         0.434
 URE6           0.283         0.283         0.284         0.284         0.284
 USUB           0.951         0.951         0.537         0.433         0.284


           Covariance Coverage
              USUB
              ________
 USUB           0.953


UNIVARIATE PROPORTIONS AND COUNTS FOR CATEGORICAL VARIABLES

    UDAT
      Category 1    0.109         3962.000
      Category 2    0.891        32552.000
    UDAY
      Category 1    0.026          959.000
      Category 2    0.974        35610.000
    UMON
      Category 1    0.016          583.000
      Category 2    0.984        35991.000
    UYER
      Category 1    0.018          649.000
      Category 2    0.982        35919.000
    UIWR
      Category 1    0.021         1200.000
      Category 2    0.020         1114.000
      Category 3    0.038         2161.000
      Category 4    0.089         5040.000
      Category 5    0.161         9106.000
      Category 6    0.439        24870.000
      Category 7    0.143         8096.000
      Category 8    0.066         3712.000
      Category 9    0.018         1026.000
      Category 10    0.005          287.000
    UDWR
      Category 1    0.105         5936.000
      Category 2    0.062         3514.000
      Category 3    0.107         6033.000
      Category 4    0.163         9247.000
      Category 5    0.186        10543.000
      Category 6    0.274        15532.000
      Category 7    0.060         3399.000
      Category 8    0.026         1488.000
      Category 9    0.011          644.000
      Category 10    0.005          273.000
    UANI
      Category 1    0.006          314.000
      Category 2    0.013          713.000
      Category 3    0.053         2968.000
      Category 4    0.134         7530.000
      Category 5    0.203        11451.000
      Category 6    0.215        12112.000
      Category 7    0.173         9749.000
      Category 8    0.104         5870.000
      Category 9    0.058         3279.000
      Category 10    0.042         2358.000
    URE3
      Category 1    0.085         2611.000
      Category 2    0.915        28252.000
    URE4
      Category 1    0.286         7069.000
      Category 2    0.714        17687.000
    URE6
      Category 1    0.667        10807.000
      Category 2    0.333         5402.000
    USUB
      Category 1    0.019         1012.000
      Category 2    0.052         2850.000
      Category 3    0.045         2470.000
      Category 4    0.101         5495.000
      Category 5    0.155         8422.000
      Category 6    0.628        34154.000


     WARNING:  THE BIVARIATE TABLE OF URE4 AND URE3 HAS AN EMPTY CELL.

     WARNING:  THE BIVARIATE TABLE OF URE4 AND URE3 HAS AN EMPTY CELL.

     WARNING:  THE BIVARIATE TABLE OF URE6 AND URE3 HAS AN EMPTY CELL.

     WARNING:  THE BIVARIATE TABLE OF URE6 AND URE3 HAS AN EMPTY CELL.

     WARNING:  THE BIVARIATE TABLE OF URE6 AND URE4 HAS AN EMPTY CELL.


THE MODEL ESTIMATION TERMINATED NORMALLY



MODEL FIT INFORMATION

Number of Free Parameters                       50

Chi-Square Test of Model Fit

          Value                           7739.625*
          Degrees of Freedom                    44
          P-Value                           0.0000

*   The chi-square value for MLM, MLMV, MLR, ULSMV, WLSM and WLSMV cannot be used
    for chi-square difference testing in the regular way.  MLM, MLR and WLSM
    chi-square difference testing is described on the Mplus website.  MLMV, WLSMV,
    and ULSMV difference testing is done using the DIFFTEST option.

RMSEA (Root Mean Square Error Of Approximation)

          Estimate                           0.055
          90 Percent C.I.                    0.054  0.056
          Probability RMSEA <= .05           0.000

CFI/TLI

          CFI                                0.970
          TLI                                0.962

Chi-Square Test of Model Fit for the Baseline Model

          Value                         253656.499
          Degrees of Freedom                    55
          P-Value                           0.0000

SRMR (Standardized Root Mean Square Residual)

          Value                              0.085

Optimum Function Value for Weighted Least-Squares Estimator

          Value                     0.56737669D-01



MODEL RESULTS

                                                    Two-Tailed
                    Estimate       S.E.  Est./S.E.    P-Value

 G        BY
    UDAT               0.476      0.008     61.701      0.000
    UDAY               0.686      0.011     64.485      0.000
