mplus_output/uni-28-SHARE_W5.out
Mplus VERSION 8.1 (Mac)
MUTHEN & MUTHEN
04/23/2020  10:56 PM

INPUT INSTRUCTIONS

  DATA:
  FILE = "uni-28-SHARE_W5.dat";

  VARIABLE:
  NAMES = mplusid UDAT UDAY UMON UYER UIWR UDWR UANI URE3 URE4 URE6 USUB;
   MISSING=.;
   CATEGORICAL ARE all; idvariable = mplusid;
  ANALYSIS:
  estimator = wlsmv; coverage=0;
  MODEL:
  g by UDAT * ;
   g by UDAY * ;
   g by UMON * ;
   g by UYER * ;
   g by UIWR * ;
   g by UDWR * ;
   g by USUB * ;
   g by URE3 * ;
   g by URE6 * ;
   g by UANI * ;
   g by URE4 * ;
   g @ 1;

  OUTPUT:
  standardized; svalues;



*** WARNING
  Data set contains cases with missing on all variables.
  These cases were not included in the analysis.
  Number of cases with missing on all variables:  1576
   1 WARNING(S) FOUND IN THE INPUT INSTRUCTIONS




SUMMARY OF ANALYSIS

Number of groups                                                 1
Number of observations                                       64670

Number of dependent variables                                   11
Number of independent variables                                  0
Number of continuous latent variables                            1

Observed dependent variables

  Binary and ordered categorical (ordinal)
   UDAT        UDAY        UMON        UYER        UIWR        UDWR
   UANI        URE3        URE4        URE6        USUB

Continuous latent variables
   G

Variables with special functions

  ID variable           MPLUSID

Estimator                                                    WLSMV
Maximum number of iterations                                  1000
Convergence criterion                                    0.500D-04
Maximum number of steepest descent iterations                   20
Maximum number of iterations for H1                           2000
Convergence criterion for H1                             0.100D-03
Parameterization                                             DELTA
Link                                                        PROBIT

Input data file(s)
  uni-28-SHARE_W5.dat

Input data format  FREE


SUMMARY OF DATA

     Number of missing data patterns           100


COVARIANCE COVERAGE OF DATA

Minimum covariance coverage value   0.000


     PROPORTION OF DATA PRESENT


           Covariance Coverage
              UDAT          UDAY          UMON          UYER          UIWR
              ________      ________      ________      ________      ________
 UDAT           0.351
 UDAY           0.351         0.351
 UMON           0.351         0.351         0.351
 UYER           0.351         0.351         0.351         0.351
 UIWR           0.346         0.347         0.347         0.346         0.992
 UDWR           0.346         0.346         0.346         0.346         0.988
 UANI           0.346         0.347         0.347         0.346         0.985
 URE3           0.303         0.303         0.303         0.304         0.302
 URE4           0.250         0.250         0.250         0.250         0.249
 URE6           0.155         0.155         0.155         0.155         0.155
 USUB           0.336         0.336         0.336         0.336         0.953


           Covariance Coverage
              UDWR          UANI          URE3          URE4          URE6
              ________      ________      ________      ________      ________
 UDWR           0.989
 UANI           0.983         0.989
 URE3           0.302         0.302         0.304
 URE4           0.249         0.249         0.250         0.250
 URE6           0.155         0.155         0.155         0.155         0.155
 USUB           0.953         0.955         0.301         0.249         0.155


           Covariance Coverage
              USUB
              ________
 USUB           0.958


UNIVARIATE PROPORTIONS AND COUNTS FOR CATEGORICAL VARIABLES

    UDAT
      Category 1    0.110         2491.000
      Category 2    0.890        20201.000
    UDAY
      Category 1    0.027          606.000
      Category 2    0.973        22119.000
    UMON
      Category 1    0.017          394.000
      Category 2    0.983        22334.000
    UYER
      Category 1    0.017          382.000
      Category 2    0.983        22337.000
    UIWR
      Category 1    0.021         1357.000
      Category 2    0.017         1076.000
      Category 3    0.035         2246.000
      Category 4    0.080         5119.000
      Category 5    0.149         9578.000
      Category 6    0.443        28436.000
      Category 7    0.155         9959.000
      Category 8    0.073         4650.000
      Category 9    0.021         1360.000
      Category 10    0.005          350.000
    UDWR
      Category 1    0.096         6146.000
      Category 2    0.058         3737.000
      Category 3    0.098         6282.000
      Category 4    0.152         9719.000
      Category 5    0.184        11772.000
      Category 6    0.292        18649.000
      Category 7    0.067         4314.000
      Category 8    0.032         2078.000
      Category 9    0.014          907.000
      Category 10    0.006          371.000
    UANI
      Category 1    0.007          424.000
      Category 2    0.012          796.000
      Category 3    0.045         2863.000
      Category 4    0.110         7055.000
      Category 5    0.180        11518.000
      Category 6    0.214        13678.000
      Category 7    0.190        12146.000
      Category 8    0.122         7777.000
      Category 9    0.069         4435.000
      Category 10    0.051         3259.000
    URE3
      Category 1    0.066         1290.000
      Category 2    0.934        18346.000
    URE4
      Category 1    0.316         5103.000
      Category 2    0.684        11071.000
    URE6
      Category 1    0.598         6012.000
      Category 2    0.402         4035.000
    USUB
      Category 1    0.016          977.000
      Category 2    0.045         2813.000
      Category 3    0.041         2514.000
      Category 4    0.092         5707.000
      Category 5    0.151         9378.000
      Category 6    0.655        40547.000


     WARNING:  THE BIVARIATE TABLE OF URE4 AND URE3 HAS AN EMPTY CELL.

     WARNING:  THE BIVARIATE TABLE OF URE4 AND URE3 HAS AN EMPTY CELL.

     WARNING:  THE BIVARIATE TABLE OF URE6 AND URE3 HAS AN EMPTY CELL.

     WARNING:  THE BIVARIATE TABLE OF URE6 AND URE3 HAS AN EMPTY CELL.

     WARNING:  THE BIVARIATE TABLE OF URE6 AND URE4 HAS AN EMPTY CELL.

     WARNING:  THE BIVARIATE TABLE OF URE6 AND URE4 HAS AN EMPTY CELL.


THE MODEL ESTIMATION TERMINATED NORMALLY



MODEL FIT INFORMATION

Number of Free Parameters                       50

Chi-Square Test of Model Fit

          Value                           5342.377*
          Degrees of Freedom                    44
          P-Value                           0.0000

*   The chi-square value for MLM, MLMV, MLR, ULSMV, WLSM and WLSMV cannot be used
    for chi-square difference testing in the regular way.  MLM, MLR and WLSM
    chi-square difference testing is described on the Mplus website.  MLMV, WLSMV,
    and ULSMV difference testing is done using the DIFFTEST option.

RMSEA (Root Mean Square Error Of Approximation)

          Estimate                           0.043
          90 Percent C.I.                    0.042  0.044
          Probability RMSEA <= .05           1.000

CFI/TLI

          CFI                                0.980
          TLI                                0.975

Chi-Square Test of Model Fit for the Baseline Model

          Value                         266657.726
          Degrees of Freedom                    55
          P-Value                           0.0000

SRMR (Standardized Root Mean Square Residual)

          Value                              0.086

Optimum Function Value for Weighted Least-Squares Estimator

          Value                     0.32074021D-01



MODEL RESULTS

                                                    Two-Tailed
                    Estimate       S.E.  Est./S.E.    P-Value

 G        BY
    UDAT               0.467      0.010     47.820      0.000
